<?xml version="1.0" encoding="UTF-8"?>
<testng-results ignored="0" total="3" passed="1" failed="1" skipped="1">
  <reporter-output>
  </reporter-output>
  <suite started-at="2022-12-09T06:32:44 IST" name="Suite" finished-at="2022-12-09T06:32:44 IST" duration-ms="119">
    <groups>
    </groups>
    <test started-at="2022-12-09T06:32:44 IST" name="Test" finished-at="2022-12-09T06:32:44 IST" duration-ms="119">
      <class name="listeners1.Demo2">
        <test-method signature="abc()[pri:0, instance:listeners1.Demo2@557caf28]" started-at="2022-12-09T06:32:44 IST" name="abc" finished-at="2022-12-09T06:32:44 IST" duration-ms="22" status="PASS">
          <reporter-output>
          </reporter-output>
        </test-method> <!-- abc -->
        <test-method signature="pqr()[pri:0, instance:listeners1.Demo2@557caf28]" started-at="2022-12-09T06:32:44 IST" name="pqr" finished-at="2022-12-09T06:32:44 IST" depends-on-methods="listeners1.Demo2.abc" duration-ms="11" status="FAIL">
          <exception class="java.lang.AssertionError">
            <message>
              <![CDATA[expected [Selenium] but found [Gmail]]]>
            </message>
            <full-stacktrace>
              <![CDATA[java.lang.AssertionError: expected [Selenium] but found [Gmail]
at org.testng.Assert.fail(Assert.java:110)
at org.testng.Assert.failNotEquals(Assert.java:1413)
at org.testng.Assert.assertEqualsImpl(Assert.java:149)
at org.testng.Assert.assertEquals(Assert.java:131)
at org.testng.Assert.assertEquals(Assert.java:655)
at org.testng.Assert.assertEquals(Assert.java:665)
at listeners1.Demo2.pqr(Demo2.java:17)
at java.base/jdk.internal.reflect.DirectMethodHandleAccessor.invoke(DirectMethodHandleAccessor.java:104)
at java.base/java.lang.reflect.Method.invoke(Method.java:578)
at org.testng.internal.invokers.MethodInvocationHelper.invokeMethod(MethodInvocationHelper.java:139)
at org.testng.internal.invokers.TestInvoker.invokeMethod(TestInvoker.java:677)
at org.testng.internal.invokers.TestInvoker.invokeTestMethod(TestInvoker.java:221)
at org.testng.internal.invokers.MethodRunner.runInSequence(MethodRunner.java:50)
at org.testng.internal.invokers.TestInvoker$MethodInvocationAgent.invoke(TestInvoker.java:962)
at org.testng.internal.invokers.TestInvoker.invokeTestMethods(TestInvoker.java:194)
at org.testng.internal.invokers.TestMethodWorker.invokeTestMethods(TestMethodWorker.java:148)
at org.testng.internal.invokers.TestMethodWorker.run(TestMethodWorker.java:128)
at java.base/java.util.ArrayList.forEach(ArrayList.java:1511)
at org.testng.TestRunner.privateRun(TestRunner.java:806)
at org.testng.TestRunner.run(TestRunner.java:601)
at org.testng.SuiteRunner.runTest(SuiteRunner.java:433)
at org.testng.SuiteRunner.runSequentially(SuiteRunner.java:427)
at org.testng.SuiteRunner.privateRun(SuiteRunner.java:387)
at org.testng.SuiteRunner.run(SuiteRunner.java:330)
at org.testng.SuiteRunnerWorker.runSuite(SuiteRunnerWorker.java:52)
at org.testng.SuiteRunnerWorker.run(SuiteRunnerWorker.java:95)
at org.testng.TestNG.runSuitesSequentially(TestNG.java:1256)
at org.testng.TestNG.runSuitesLocally(TestNG.java:1176)
at org.testng.TestNG.runSuites(TestNG.java:1099)
at org.testng.TestNG.run(TestNG.java:1067)
at org.testng.remote.AbstractRemoteTestNG.run(AbstractRemoteTestNG.java:115)
at org.testng.remote.RemoteTestNG.initAndRun(RemoteTestNG.java:251)
at org.testng.remote.RemoteTestNG.main(RemoteTestNG.java:77)
]]>
            </full-stacktrace>
          </exception> <!-- java.lang.AssertionError -->
          <reporter-output>
          </reporter-output>
        </test-method> <!-- pqr -->
        <test-method signature="xyz()[pri:0, instance:listeners1.Demo2@557caf28]" started-at="2022-12-09T06:32:44 IST" name="xyz" finished-at="2022-12-09T06:32:44 IST" depends-on-methods="listeners1.Demo2.pqr" duration-ms="1" status="SKIP">
          <exception class="java.lang.Throwable">
            <message>
              <![CDATA[Method listeners1.Demo2.xyz() on instance listeners1.Demo2@557caf28 depends on not successfully finished methods 
[listeners1.Demo2.pqr() on instance listeners1.Demo2@557caf28]]]>
            </message>
            <full-stacktrace>
              <![CDATA[java.lang.Throwable: Method listeners1.Demo2.xyz() on instance listeners1.Demo2@557caf28 depends on not successfully finished methods 
[listeners1.Demo2.pqr() on instance listeners1.Demo2@557caf28]
at org.testng.internal.invokers.TestInvoker.invokeTestMethods(TestInvoker.java:150)
at org.testng.internal.invokers.TestMethodWorker.invokeTestMethods(TestMethodWorker.java:148)
at org.testng.internal.invokers.TestMethodWorker.run(TestMethodWorker.java:128)
at java.base/java.util.ArrayList.forEach(ArrayList.java:1511)
at org.testng.TestRunner.privateRun(TestRunner.java:806)
at org.testng.TestRunner.run(TestRunner.java:601)
at org.testng.SuiteRunner.runTest(SuiteRunner.java:433)
at org.testng.SuiteRunner.runSequentially(SuiteRunner.java:427)
at org.testng.SuiteRunner.privateRun(SuiteRunner.java:387)
at org.testng.SuiteRunner.run(SuiteRunner.java:330)
at org.testng.SuiteRunnerWorker.runSuite(SuiteRunnerWorker.java:52)
at org.testng.SuiteRunnerWorker.run(SuiteRunnerWorker.java:95)
at org.testng.TestNG.runSuitesSequentially(TestNG.java:1256)
at org.testng.TestNG.runSuitesLocally(TestNG.java:1176)
at org.testng.TestNG.runSuites(TestNG.java:1099)
at org.testng.TestNG.run(TestNG.java:1067)
at org.testng.remote.AbstractRemoteTestNG.run(AbstractRemoteTestNG.java:115)
at org.testng.remote.RemoteTestNG.initAndRun(RemoteTestNG.java:251)
at org.testng.remote.RemoteTestNG.main(RemoteTestNG.java:77)
]]>
            </full-stacktrace>
          </exception> <!-- java.lang.Throwable -->
          <reporter-output>
          </reporter-output>
        </test-method> <!-- xyz -->
      </class> <!-- listeners1.Demo2 -->
    </test> <!-- Test -->
  </suite> <!-- Suite -->
</testng-results>
